<?xml version="1.0" ?>
<robot name="cessna_c172">
  <!-- joints -->  
  <joint name="cessna_c172__left_flap_joint" type="revolute">
    <parent link="cessna_c172__body"/>
    <child link="cessna_c172__left_flap"/>
    <origin xyz="-1.6    1.55   1.925" rpy="0.02 0   0"/>
    <axis xyz="0 1 0"/>
    <dynamics damping="1.000"/>
    <limit lower="-0.53" upper="0.53" effort="-1.0" velocity="-1.0"/>
  </joint>

  <joint name="cessna_c172__left_aileron_joint" type="revolute">
    <parent link="cessna_c172__body"/>
    <child link="cessna_c172__left_aileron"/>
    <origin xyz="-1.45   3.7    1.995" rpy="0.05  0   -0.12"/>
    <axis xyz="0 1 0"/>
    <dynamics damping="1.000"/>
    <limit lower="-0.53" upper="0.53" effort="-1.0" velocity="-1.0"/>
  </joint>

  <joint name="cessna_c172__right_flap_joint" type="revolute">
    <parent link="cessna_c172__body"/>
    <child link="cessna_c172__right_flap"/>
    <origin xyz="-1.6   -1.55   1.925" rpy="-0.02  0    0"/>
    <axis xyz="0 1 0"/>
    <dynamics damping="1.000"/>
    <limit lower="-0.53" upper="0.53" effort="-1.0" velocity="-1.0"/>
  </joint>

  <joint name="cessna_c172__right_aileron_joint" type="revolute">
    <parent link="cessna_c172__body"/>
    <child link="cessna_c172__right_aileron"/>
    <origin xyz="-1.45  -3.7    1.995" rpy="-0.05  0    0.12"/>
    <axis xyz="0 1 0"/>
    <dynamics damping="1.000"/>
    <limit lower="-0.53" upper="0.53" effort="-1.0" velocity="-1.0"/>
  </joint>

  <joint name="cessna_c172__elevators_joint" type="revolute">
    <parent link="cessna_c172__body"/>
    <child link="cessna_c172__elevators"/>
    <origin xyz="-5.55   0     1.065" rpy="0 0 0"/>
    <axis xyz="0 1 0"/>
    <dynamics damping="1.000"/>
    <limit lower="-0.53" upper="0.53" effort="-1.0" velocity="-1.0"/>
  </joint>

  <joint name="cessna_c172__rudder_joint" type="revolute">
    <parent link="cessna_c172__body"/>
    <child link="cessna_c172__rudder"/>
    <origin xyz="-5.9    0     1.795" rpy="0   -0.35  0"/>
    <axis xyz="0 0 1"/>
    <dynamics damping="1.000"/>
    <limit lower="-0.53" upper="0.53" effort="-1.0" velocity="-1.0"/>
  </joint>

  <joint name="cessna_c172__propeller_joint" type="revolute">
    <parent link="cessna_c172__body"/>
    <child link="cessna_c172__propeller"/>
    <origin xyz="1.79 0   1.35" rpy="0 0 0"/>
    <axis xyz="1 0 0"/>
    <dynamics damping="0.001"/>
    <limit lower="-1000000000000.0" upper="1000000000000.0" effort="-1.0" velocity="-1.0"/>
  </joint>

  <joint name="cessna_c172__front_wheel_joint" type="revolute">
    <parent link="cessna_c172__body"/>
    <child link="cessna_c172__front_wheel"/>
    <origin xyz="0.712 0    0.182" rpy="0 0 0"/>
    <axis xyz="0 1 0"/>
    <limit lower="-1000000000000.0" upper="1000000000000.0" effort="-1.0" velocity="-1.0"/>
    <dynamics damping="0.010" friction="0.3"/>
  </joint>
  
  <joint name="cessna_c172__rear_left_wheel_joint" type="revolute">
    <parent link="cessna_c172__body"/>
    <child link="cessna_c172__rear_left_wheel"/>
    <origin xyz="-1    -1.27   0.245" rpy="0 0 0"/>
    <axis xyz="0 1 0"/>
    <dynamics damping="0.010" friction="0.3"/>
    <limit lower="-1000000000000.0" upper="1000000000000.0" effort="-1.0" velocity="-1.0"/>
  </joint>

  <joint name="cessna_c172__rear_right_wheel_joint" type="revolute">
    <parent link="cessna_c172__body"/>
    <child link="cessna_c172__rear_right_wheel"/>
    <origin xyz="-1     1.27   0.245" rpy="0 0 0"/>
    <axis xyz="0 1 0"/>
    <dynamics damping="0.010" friction="0.3"/>
    <limit lower="-1000000000000.0" upper="1000000000000.0" effort="-1.0" velocity="-1.0"/>
  </joint>
  

  <joint name="dummy_joint" type="fixed">
     <parent link="dummy"/>
     <child link="cessna_c172__body"/>
  </joint>

  <!-- links  -->
  <!-- <link name="wing_body_debug_visuals">
        <pose>0 0 0.495 0 0 0</pose>
        <gravity>0</gravity>
  </link> -->

  <link name="dummy"> <!-- blade_1_visual -->
  </link>

  <link name="cessna_c172__body">
    <inertial>
      <mass value="680.389"/>
      <origin xyz="-0.0414  0      0.9271" rpy="0 0 0"/>
      <inertia ixx="1285.315427874" ixy="0.0" ixz="0.0" iyy="1824.930976707" iyz="0.0" izz="2666.893931043"/>
    </inertial>
    <collision name="cessna_c172__collision">
      <origin xyz="0    0    0.495" rpy="0 0 0"/>
      <geometry>
        <mesh filename="package://gazebo_models/cessna_c172/meshes/body.dae" scale="1.0 1.0 1.0"/>
      </geometry>
    </collision>
    <visual name="cessna_c172__visual">
      <origin xyz="0    0    0.495" rpy="0 0 0"/>
      <geometry>
        <mesh filename="package://gazebo_models/cessna_c172/meshes/body.dae" scale="1.0 1.0 1.0"/>
      </geometry>
    </visual>
  </link>

  <link name="cessna_c172__left_aileron">
    <inertial>
      <mass value="2"/>
      <origin xyz="-1.65  3.7   1.5" rpy="0.05  0   -0.12"/>
      <inertia ixx="0.8434" ixy="0.0" ixz="0.0" iyy="0.0119" iyz="0.0" izz="0.855"/>
    </inertial>
    <collision name="cessna_c172__collision">
      <origin xyz="1.8825 -3.5704 -1.3232" rpy="-0.04964  0.00598  0.11985"/>
      <geometry>
        <mesh filename="package://gazebo_models/cessna_c172/meshes/left_aileron.dae" scale="1.0 1.0 1.0"/>
      </geometry>
    </collision>
    <visual name="cessna_c172__visual">
      <origin xyz="1.8825 -3.5704 -1.3232" rpy="-0.04964  0.00598  0.11985"/>
      <geometry>
        <mesh filename="package://gazebo_models/cessna_c172/meshes/left_aileron.dae" scale="1.0 1.0 1.0"/>
      </geometry>
    </visual>
  </link>

  <link name="cessna_c172__left_flap">
    <inertial>
      <mass value="2"/>
      <origin xyz="-1.8   1.55  1.43" rpy="0.02 0   0"/>
      <inertia ixx="0.6747" ixy="0.0" ixz="0.0" iyy="0.0242" iyz="0.0" izz="0.6962"/>
    </inertial>
    <collision name="cessna_c172__collision">
      <origin xyz="1.6     -1.57828 -1.39871" rpy="-0.02  0    0"/>
      <geometry>
        <mesh filename="package://gazebo_models/cessna_c172/meshes/left_flap.dae" scale="1.0 1.0 1.0"/>
      </geometry>
    </collision>
    <visual name="cessna_c172__visual">
      <origin xyz="1.6     -1.57828 -1.39871" rpy="-0.02  0    0"/>
      <geometry>
        <mesh filename="package://gazebo_models/cessna_c172/meshes/left_flap.dae" scale="1.0 1.0 1.0"/>
      </geometry>
    </visual>
  </link>

  <link name="cessna_c172__right_aileron">
    <inertial>
      <mass value="2"/>
      <origin xyz="-1.65 -3.7   1.5" rpy="-0.05  0    0.12"/>
      <inertia ixx="0.8434" ixy="0.0" ixz="0.0" iyy="0.0119" iyz="0.0" izz="0.855"/>
    </inertial>
    <collision name="cessna_c172__collision">
      <origin xyz="1.8825  3.5704 -1.3232" rpy="0.04964  0.00598 -0.11985"/>
      <geometry>
        <mesh filename="package://gazebo_models/cessna_c172/meshes/right_aileron.dae" scale="1.0 1.0 1.0"/>
      </geometry>
    </collision>
    <visual name="cessna_c172__visual">
      <origin xyz="1.8825  3.5704 -1.3232" rpy="0.04964  0.00598 -0.11985"/>
      <geometry>
        <mesh filename="package://gazebo_models/cessna_c172/meshes/right_aileron.dae" scale="1.0 1.0 1.0"/>
      </geometry>
    </visual>
  </link>

  <link name="cessna_c172__right_flap">
    <inertial>
      <mass value="2"/>
      <origin xyz="-1.8  -1.55  1.43" rpy="-0.02  0    0"/>
      <inertia ixx="0.6747" ixy="0.0" ixz="0.0" iyy="0.0242" iyz="0.0" izz="0.6962"/>
    </inertial>
    <collision name="cessna_c172__collision">
      <origin xyz="1.6      1.57828 -1.39871" rpy="0.02 0   0"/>
      <geometry>
        <mesh filename="package://gazebo_models/cessna_c172/meshes/right_flap.dae" scale="1.0 1.0 1.0"/>
      </geometry>
    </collision>
    <visual name="cessna_c172__visual">
      <origin xyz="1.6      1.57828 -1.39871" rpy="0.02 0   0"/>
      <geometry>
        <mesh filename="package://gazebo_models/cessna_c172/meshes/right_flap.dae" scale="1.0 1.0 1.0"/>
      </geometry>
    </visual>
  </link>

  <link name="cessna_c172__elevators">
    <inertial>
      <mass value="2"/>
      <origin xyz="-5.75     0       0.56999" rpy="0 0 0"/>
      <inertia ixx="1.5008" ixy="0.0" ixz="0.0" iyy="0.0274" iyz="0.0" izz="1.5266"/>
    </inertial>
    <collision name="cessna_c172__collision">
      <origin xyz="5.55     0      -0.56999" rpy="0 0 0"/>
      <geometry>
        <mesh filename="package://gazebo_models/cessna_c172/meshes/elevators.dae" scale="1.0 1.0 1.0"/>
      </geometry>
    </collision>
    <visual name="cessna_c172__visual">
      <origin xyz="5.55     0      -0.56999" rpy="0 0 0"/>
      <geometry>
        <mesh filename="package://gazebo_models/cessna_c172/meshes/elevators.dae" scale="1.0 1.0 1.0"/>
      </geometry>
    </visual>
  </link>

  <link name="cessna_c172__rudder">
    <inertial>
      <mass value="2"/>
      <origin xyz="-6.1  0   1.3" rpy="0   -0.35  0"/>
      <inertia ixx="0.4708" ixy="0.0" ixz="0.0" iyy="0.5208" iyz="0.0" izz="0.0508"/>
    </inertial>
    <collision name="cessna_c172__collision">
      <origin xyz="5.09653  0      -3.24428" rpy="0   0.35 0"/>
      <geometry>
        <mesh filename="package://gazebo_models/cessna_c172/meshes/rudder.dae" scale="1.0 1.0 1.0"/>
      </geometry>
    </collision>
    <visual name="cessna_c172__visual">
      <origin xyz="5.09653  0      -3.24428" rpy="0   0.35 0"/>
      <geometry>
        <mesh filename="package://gazebo_models/cessna_c172/meshes/rudder.dae" scale="1.0 1.0 1.0"/>
      </geometry>
    </visual>
  </link>

  <link name="cessna_c172__propeller">
    <inertial>
      <mass value="18.37"/>
      <origin xyz="-0.35  0    0" rpy="0 0 0"/>
      <inertia ixx="7.5067" ixy="0" ixz="0" iyy="7.5150" iyz="0" izz="0.068275"/>
    </inertial>
    <collision name="cessna_c172__collision">
      <origin xyz="0 0 0" rpy="0 0 0"/>
      <geometry>
        <mesh filename="package://gazebo_models/cessna_c172/meshes/cessna_prop.dae" scale="1.0 1.0 1.0"/>
      </geometry>
    </collision>
    <visual name="cessna_c172__visual">
      <origin xyz="0 0 0" rpy="0 0 0"/>
      <geometry>
        <mesh filename="package://gazebo_models/cessna_c172/meshes/cessna_prop.dae" scale="1.0 1.0 1.0"/>
      </geometry>
    </visual>
  </link>

  <link name="cessna_c172__front_wheel">
    <inertial>
      <mass value="2"/>
      <origin xyz="0.712  0    -0.313" rpy="1.57079 0      0"/>
      <inertia ixx="0.01786" ixy="0" ixz="0" iyy="0.01786" iyz="0" izz="0.0324"/>
    </inertial>
    <collision name="cessna_c172__collision">
      <origin xyz="0 0 0" rpy="1.57079 0      0"/>
      <geometry>
        <cylinder radius="0.18" length="0.1"/>
      </geometry>
    </collision>
    <visual name="cessna_c172__visual">
      <origin xyz="-0.712  0     0.313" rpy="0 0 0"/>
      <geometry>
        <mesh filename="package://gazebo_models/cessna_c172/meshes/cessna_front_wheel.dae" scale="1.0 1.0 1.0"/>
      </geometry>
    </visual>
  </link>

  <link name="cessna_c172__rear_left_wheel">
    <inertial>
      <mass value="2"/>
      <origin xyz="-1    1.27 -0.25" rpy="1.57079 0      0"/>
      <inertia ixx="0.035516" ixy="0" ixz="0" iyy="0.035516" iyz="0" izz="0.0625"/>
    </inertial>
    <collision name="cessna_c172__collision">
      <origin xyz="0   2.54 0" rpy="1.57079 0      0"/>
      <geometry>
        <cylinder radius="0.25" length="0.16"/>
      </geometry>
    </collision>
    <visual name="cessna_c172__visual">
      <origin xyz="1   1.27 0.25" rpy="0 0 0"/>
      <geometry>
        <mesh filename="package://gazebo_models/cessna_c172/meshes/cessna_rear_left_wheel.dae" scale="1.0 1.0 1.0"/>
      </geometry>
    </visual>
  </link>

  <link name="cessna_c172__rear_right_wheel">
    <inertial>
      <mass value="2"/>
      <origin xyz="-1   -1.27 -0.25" rpy="1.57079 0      0"/>
      <inertia ixx="0.035516" ixy="0" ixz="0" iyy="0.035516" iyz="0" izz="0.0625"/>
    </inertial>
    <collision name="cessna_c172__collision">
      <origin xyz="0   -2.54  0" rpy="1.57079 0      0"/>
      <geometry>
        <cylinder radius="0.25" length="0.16"/>
      </geometry>
    </collision>
    <visual name="cessna_c172__visual">
      <origin xyz="1   -1.27  0.25" rpy="0 0 0"/>
      <geometry>
        <mesh filename="package://gazebo_models/cessna_c172/meshes/cessna_rear_right_wheel.dae" scale="1.0 1.0 1.0"/>
      </geometry>
    </visual>
  </link>

  <!-- Transmissions -->
  <transmission name="tran1">
    <type>transmission_interface/SimpleTransmission</type>
    <joint name="cessna_c172__left_flap_joint">
      <hardwareInterface>hardware_interface/EffortJointInterface</hardwareInterface>
    </joint>
    <actuator name="motor1">
      <hardwareInterface>hardware_interface/EffortJointInterface</hardwareInterface>
      <mechanicalReduction>1</mechanicalReduction>
    </actuator>
  </transmission>

  <transmission name="tran2">
    <type>transmission_interface/SimpleTransmission</type>
    <joint name="cessna_c172__left_aileron_joint">
      <hardwareInterface>hardware_interface/EffortJointInterface</hardwareInterface>
    </joint>
    <actuator name="motor2">
      <hardwareInterface>hardware_interface/EffortJointInterface</hardwareInterface>
      <mechanicalReduction>1</mechanicalReduction>
    </actuator>
  </transmission>

  <transmission name="tran3">
    <type>transmission_interface/SimpleTransmission</type>
    <joint name="cessna_c172__right_flap_joint">
      <hardwareInterface>hardware_interface/EffortJointInterface</hardwareInterface>
    </joint>
    <actuator name="motor3">
      <hardwareInterface>hardware_interface/EffortJointInterface</hardwareInterface>
      <mechanicalReduction>1</mechanicalReduction>
    </actuator>
  </transmission>
 
  <transmission name="tran4">
    <type>transmission_interface/SimpleTransmission</type>
    <joint name="cessna_c172__right_aileron_joint">
      <hardwareInterface>hardware_interface/EffortJointInterface</hardwareInterface>
    </joint>
    <actuator name="motor4">
      <hardwareInterface>hardware_interface/EffortJointInterface</hardwareInterface>
      <mechanicalReduction>1</mechanicalReduction>
    </actuator>
  </transmission>

  <transmission name="tran5">
    <type>transmission_interface/SimpleTransmission</type>
    <joint name="cessna_c172__elevators_joint">
      <hardwareInterface>hardware_interface/EffortJointInterface</hardwareInterface>
    </joint>
    <actuator name="motor5">
      <hardwareInterface>hardware_interface/EffortJointInterface</hardwareInterface>
      <mechanicalReduction>1</mechanicalReduction>
    </actuator>
  </transmission>

  <transmission name="tran6">
    <type>transmission_interface/SimpleTransmission</type>
    <joint name="cessna_c172__rudder_joint">
      <hardwareInterface>hardware_interface/EffortJointInterface</hardwareInterface>
    </joint>
    <actuator name="motor6">
      <hardwareInterface>hardware_interface/EffortJointInterface</hardwareInterface>
      <mechanicalReduction>1</mechanicalReduction>
    </actuator>
  </transmission>

  <transmission name="tran7">
    <type>transmission_interface/SimpleTransmission</type>
    <joint name="cessna_c172__propeller_joint">
      <hardwareInterface>hardware_interface/EffortJointInterface</hardwareInterface>
    </joint>
    <actuator name="motor7">
      <hardwareInterface>hardware_interface/EffortJointInterface</hardwareInterface>
      <mechanicalReduction>1</mechanicalReduction>
    </actuator>
  </transmission>

  <transmission name="tran8">
    <type>transmission_interface/SimpleTransmission</type>
    <joint name="cessna_c172__front_wheel_joint">
      <hardwareInterface>hardware_interface/EffortJointInterface</hardwareInterface>
    </joint>
    <actuator name="motor8">
      <hardwareInterface>hardware_interface/EffortJointInterface</hardwareInterface>
      <mechanicalReduction>1</mechanicalReduction>
    </actuator>
  </transmission>

  <transmission name="tran9">
    <type>transmission_interface/SimpleTransmission</type>
    <joint name="cessna_c172__rear_left_wheel_joint">
      <hardwareInterface>hardware_interface/EffortJointInterface</hardwareInterface>
    </joint>
    <actuator name="motor9">
      <hardwareInterface>hardware_interface/EffortJointInterface</hardwareInterface>
      <mechanicalReduction>1</mechanicalReduction>
    </actuator>
  </transmission>

  <transmission name="tran10">
    <type>transmission_interface/SimpleTransmission</type>
    <joint name="cessna_c172__rear_right_wheel_joint">
      <hardwareInterface>hardware_interface/EffortJointInterface</hardwareInterface>
    </joint>
    <actuator name="motor10">
      <hardwareInterface>hardware_interface/EffortJointInterface</hardwareInterface>
      <mechanicalReduction>1</mechanicalReduction>
    </actuator>
  </transmission>
  
  <!-- plugins -->
  <gazebo>
      <plugin name="p3d_base_controller" filename="libgazebo_ros_p3d.so">
          <alwaysOn>true</alwaysOn>
          <updateRate>1000.0</updateRate>
          <bodyName>cessna_c172__body</bodyName>
          <topicName>/uav4/position</topicName>
          <gaussianNoise>0.01</gaussianNoise>
          <frameName>cessna_c172__body</frameName>
          <xyzOffsets>0 0 0</xyzOffsets>
          <rpyOffsets>0 0 0</rpyOffsets>
      </plugin>
  </gazebo>

</robot>
